Workbook

Sheet Ringkasan
A1: JastipKita — Model Bisnis & Proyeksi Keuangan 24 Bulan
A2: Untuk Direksi & Dewan Komisaris. Pra-launch: seluruh integrasi MOCK/SANDBOX, belum ada transaksi nyata. Bukan nasihat keuangan/investasi; angka berstatus ASUMSI wajib diganti data beta.
A3: ="Skenario aktif (ubah di Asumsi!D4): "&Asumsi!$D$4 -> Skenario aktif (ubah di Asumsi!D4): Dasar
A4: Soft launch (Bulan 1): | C4: =Asumsi!$G$10 -> 46419 | D4: ="Bulan 0 = pra-peluncuran (biaya sekali + "&Asumsi!$G$11&" bulan biaya tim & infra)" -> Bulan 0 = pra-peluncuran (biaya sekali + 3 bulan biaya tim & infra)
B6: KPI | C6: Satuan | D6: Konservatif | E6: Dasar | F6: Optimis | G6: Skenario aktif | H6: Definisi / catatan
A7: Volume
B8: Transaksi selesai — Tahun 1 | C8: transaksi | D8: ='Proyeksi 24 Bulan'!$AB$38 -> 649.033 | E8: ='Proyeksi 24 Bulan'!$AB$101 -> 1581.9758 | F8: ='Proyeksi 24 Bulan'!$AB$164 -> 3445.195 | G8: =CHOOSE(Asumsi!$D$5,D8,E8,F8) -> 1581.9758 | H8: B1–B12, status COMPLETED
B9: Transaksi selesai — Tahun 2 | C9: transaksi | D9: ='Proyeksi 24 Bulan'!$AC$38 -> 1621.4578 | E9: ='Proyeksi 24 Bulan'!$AC$101 -> 5230.5395 | F9: ='Proyeksi 24 Bulan'!$AC$164 -> 11620.519 | G9: =CHOOSE(Asumsi!$D$5,D9,E9,F9) -> 5230.5395 | H9: B13–B24
B10: Transaksi selesai — Bulan 24 | C10: trx/bulan | D10: ='Proyeksi 24 Bulan'!$AA$38 -> 178.16361 | E10: ='Proyeksi 24 Bulan'!$AA$101 -> 589.45116 | F10: ='Proyeksi 24 Bulan'!$AA$164 -> 1424.8058 | G10: =CHOOSE(Asumsi!$D$5,D10,E10,F10) -> 589.45116 | H10: run-rate akhir periode
B11: Traveler aktif — Bulan 24 | C11: orang | D11: ='Proyeksi 24 Bulan'!$AA$21 -> 77.462439 | E11: ='Proyeksi 24 Bulan'!$AA$84 -> 263.63022 | F11: ='Proyeksi 24 Bulan'!$AA$147 -> 983.66545 | G11: =CHOOSE(Asumsi!$D$5,D11,E11,F11) -> 263.63022 | H11: traveler dengan trip aktif
B12: Basis pembeli — Bulan 24 | C12: orang | D12: ='Proyeksi 24 Bulan'!$AA$36 -> 966.71415 | E12: ='Proyeksi 24 Bulan'!$AA$99 -> 2811.658 | F12: ='Proyeksi 24 Bulan'!$AA$162 -> 6302.4713 | G12: =CHOOSE(Asumsi!$D$5,D12,E12,F12) -> 2811.658 | H12: setelah churn
B13: Fill rate (likuiditas) — Tahun 2 | C13: % | D13: ='Proyeksi 24 Bulan'!$AC$35 -> 0.71805297 | E13: ='Proyeksi 24 Bulan'!$AC$98 -> 0.98504664 | F13: ='Proyeksi 24 Bulan'!$AC$161 -> 1 | G13: =CHOOSE(Asumsi!$D$5,D13,E13,F13) -> 0.98504664 | H13: transaksi dibayar ÷ permintaan
B14: Sisi pembatas — Bulan 24 | C14: teks | D14: ='Proyeksi 24 Bulan'!$AA$39 -> Pasokan | E14: ='Proyeksi 24 Bulan'!$AA$102 -> Permintaan | F14: ='Proyeksi 24 Bulan'!$AA$165 -> Permintaan | G14: =CHOOSE(Asumsi!$D$5,D14,E14,F14) -> Permintaan | H14: Pasokan = traveler kurang; Permintaan = pembeli kurang
A15: Nilai & pendapatan (Rp juta)
B16: GMV — Tahun 1 | C16: Rp juta | D16: ='Proyeksi 24 Bulan'!$AB$41/1000000 -> 1420.2904 | E16: ='Proyeksi 24 Bulan'!$AB$104/1000000 -> 4619.5808 | F16: ='Proyeksi 24 Bulan'!$AB$167/1000000 -> 12588.696 | G16: =CHOOSE(Asumsi!$D$5,D16,E16,F16) -> 4619.5808 | H16: Σ TOTAL transaksi selesai (launch-plan §8), sebelum promo & credit
B17: GMV — Tahun 2 | C17: Rp juta | D17: ='Proyeksi 24 Bulan'!$AC$41/1000000 -> 3548.2647 | E17: ='Proyeksi 24 Bulan'!$AC$104/1000000 -> 15273.874 | F17: ='Proyeksi 24 Bulan'!$AC$167/1000000 -> 42461.217 | G17: =CHOOSE(Asumsi!$D$5,D17,E17,F17) -> 15273.874
B18: GMV run-rate tahunan — Bulan 24 | C18: Rp juta | D18: ='Proyeksi 24 Bulan'!$AA$41*12/1000000 -> 4678.5429 | E18: ='Proyeksi 24 Bulan'!$AA$104*12/1000000 -> 20655.314 | F18: ='Proyeksi 24 Bulan'!$AA$167*12/1000000 -> 62474.652 | G18: =CHOOSE(Asumsi!$D$5,D18,E18,F18) -> 20655.314 | H18: GMV bulan 24 × 12
B19: Take rate bruto — Tahun 2 | C19: % | D19: ='Proyeksi 24 Bulan'!$AC$48 -> 0.044554774 | E19: ='Proyeksi 24 Bulan'!$AC$111 -> 0.04451851 | F19: ='Proyeksi 24 Bulan'!$AC$174 -> 0.044471977 | G19: =CHOOSE(Asumsi!$D$5,D19,E19,F19) -> 0.04451851 | H19: (platform + protection fee) ÷ GMV
B20: Take rate bersih — Tahun 2 | C20: % | D20: ='Proyeksi 24 Bulan'!$AC$49 -> 0.041946504 | E20: ='Proyeksi 24 Bulan'!$AC$112 -> 0.042086535 | F20: ='Proyeksi 24 Bulan'!$AC$175 -> 0.042131851 | G20: =CHOOSE(Asumsi!$D$5,D20,E20,F20) -> 0.042086535 | H20: setelah promo & credit referral
B21: Pendapatan bersih — Tahun 1 | C21: Rp juta | D21: ='Proyeksi 24 Bulan'!$AB$47/1000000 -> 58.087935 | E21: ='Proyeksi 24 Bulan'!$AB$110/1000000 -> 191.71895 | F21: ='Proyeksi 24 Bulan'!$AB$173/1000000 -> 525.97632 | G21: =CHOOSE(Asumsi!$D$5,D21,E21,F21) -> 191.71895 | H21: bea, pajak impor, PPN, harga barang & traveler fee = pass-through
B22: Pendapatan bersih — Tahun 2 | C22: Rp juta | D22: ='Proyeksi 24 Bulan'!$AC$47/1000000 -> 148.8373 | E22: ='Proyeksi 24 Bulan'!$AC$110/1000000 -> 642.82445 | F22: ='Proyeksi 24 Bulan'!$AC$173/1000000 -> 1788.9697 | G22: =CHOOSE(Asumsi!$D$5,D22,E22,F22) -> 642.82445
A23: Unit economics per transaksi representatif (Rp)
B24: Nilai barang rata-rata | C24: Rp | D24: ='Unit Economics'!$C$8 -> 1500000 | E24: ='Unit Economics'!$D$8 -> 2000000 | F24: ='Unit Economics'!$E$8 -> 2500000 | G24: =CHOOSE(Asumsi!$D$5,D24,E24,F24) -> 2000000 | H24: ASUMSI skenario
B25: TOTAL dibayar pembeli (11 baris) | C25: Rp | D25: ='Unit Economics'!$C$18 -> 2188317.7 | E25: ='Unit Economics'!$D$18 -> 2920133.6 | F25: ='Unit Economics'!$E$18 -> 3653986.4 | G25: =CHOOSE(Asumsi!$D$5,D25,E25,F25) -> 2920133.6 | H25: Unit Economics baris 11
B26: Pendapatan bruto platform | C26: Rp | D26: ='Unit Economics'!$C$47 -> 97500 | E26: ='Unit Economics'!$D$47 -> 130000 | F26: ='Unit Economics'!$E$47 -> 162500 | G26: =CHOOSE(Asumsi!$D$5,D26,E26,F26) -> 130000 | H26: platform fee 5% + protection 1,5% (clamp config)
B27: Subsidi kanal pembayaran | C27: Rp | D27: ='Unit Economics'!$C$35 -> 14637.8 | E27: ='Unit Economics'!$D$35 -> 16233.3 | F27: ='Unit Economics'!$E$35 -> 16528.14 | G27: =CHOOSE(Asumsi!$D$5,D27,E27,F27) -> 16233.3 | H27: biaya Xendit publik − biaya dibebankan (launch-checklist B4)
B28: Margin kontribusi per transaksi | C28: Rp | D28: ='Unit Economics'!$C$57 -> 19350.475 | E28: ='Unit Economics'!$D$57 -> 77258.008 | F28: ='Unit Economics'!$E$57 -> 110884.07 | G28: =CHOOSE(Asumsi!$D$5,D28,E28,F28) -> 77258.008 | H28: setelah promo, referral, subsidi, payout, klaim, CS, chargeback, batal
B29: Margin kontribusi ÷ pendapatan bersih | C29: % | D29: ='Unit Economics'!$C$59 -> 0.21080723 | E29: ='Unit Economics'!$D$59 -> 0.62863362 | F29: ='Unit Economics'!$E$59 -> 0.72026397 | G29: =CHOOSE(Asumsi!$D$5,D29,E29,F29) -> 0.62863362
B30: BEP transaksi/bulan (biaya tetap + marketing) | C30: trx/bulan | D30: =IF('Unit Economics'!$C$57>0,ROUNDUP(('Proyeksi 24 Bulan'!$AC$71-'Proyeksi 24 Bulan'!$AC$69)/12/'Unit Economics'!$C$57,0),"CM ≤ 0") -> 8470 | E30: =IF('Unit Economics'!$D$57>0,ROUNDUP(('Proyeksi 24 Bulan'!$AC$134-'Proyeksi 24 Bulan'!$AC$132)/12/'Unit Economics'!$D$57,0),"CM ≤ 0") -> 2122 | F30: =IF('Unit Economics'!$E$57>0,ROUNDUP(('Proyeksi 24 Bulan'!$AC$197-'Proyeksi 24 Bulan'!$AC$195)/12/'Unit Economics'!$E$57,0),"CM ≤ 0") -> 1479 | G30: =CHOOSE(Asumsi!$D$5,D30,E30,F30) -> 2122 | H30: rata-rata biaya Th2 (tanpa biaya sekali) ÷ margin kontribusi per transaksi
B31: BEP transaksi/bulan (hanya biaya tetap) | C31: trx/bulan | D31: =IF('Unit Economics'!$C$57>0,ROUNDUP(('Proyeksi 24 Bulan'!$AC$71-'Proyeksi 24 Bulan'!$AC$69-'Proyeksi 24 Bulan'!$AC$63)/12/'Unit Economics'!$C$57,0),"CM ≤ 0") -> 6661 | E31: =IF('Unit Economics'!$D$57>0,ROUNDUP(('Proyeksi 24 Bulan'!$AC$134-'Proyeksi 24 Bulan'!$AC$132-'Proyeksi 24 Bulan'!$AC$126)/12/'Unit Economics'!$D$57,0),"CM ≤ 0") -> 1669 | F31: =IF('Unit Economics'!$E$57>0,ROUNDUP(('Proyeksi 24 Bulan'!$AC$197-'Proyeksi 24 Bulan'!$AC$195-'Proyeksi 24 Bulan'!$AC$189)/12/'Unit Economics'!$E$57,0),"CM ≤ 0") -> 1163 | G31: =CHOOSE(Asumsi!$D$5,D31,E31,F31) -> 1669 | H31: tanpa marketing
B32: Transaksi Bulan 24 ÷ BEP (biaya tetap + marketing) | C32: % | D32: =IF(ISNUMBER(D30),'Proyeksi 24 Bulan'!$AA$38/D30,0) -> 0.021034665 | E32: =IF(ISNUMBER(E30),'Proyeksi 24 Bulan'!$AA$101/E30,0) -> 0.27778094 | F32: =IF(ISNUMBER(F30),'Proyeksi 24 Bulan'!$AA$164/F30,0) -> 0.96335755 | G32: =CHOOSE(Asumsi!$D$5,D32,E32,F32) -> 0.27778094 | H32: ≥ 100% = volume sudah menutup biaya
B33: Status CAC vs LTV 12 bulan | C33: teks | D33: ='Unit Economics'!$C$72 -> Melewati guardrail | E33: ='Unit Economics'!$D$72 -> Melewati guardrail | F33: ='Unit Economics'!$E$72 -> Melewati guardrail | G33: =CHOOSE(Asumsi!$D$5,D33,E33,F33) -> Melewati guardrail | H33: guardrail config: CAC ≤ 0,33 × LTV
A34: Laba & kas (Rp juta)
B35: Margin kontribusi — Tahun 1 | C35: Rp juta | D35: ='Proyeksi 24 Bulan'!$AB$60/1000000 -> -16.083381 | E35: ='Proyeksi 24 Bulan'!$AB$123/1000000 -> 89.376021 | F35: ='Proyeksi 24 Bulan'!$AB$186/1000000 -> 338.29874 | G35: =CHOOSE(Asumsi!$D$5,D35,E35,F35) -> 89.376021
B36: Margin kontribusi — Tahun 2 | C36: Rp juta | D36: ='Proyeksi 24 Bulan'!$AC$60/1000000 -> -17.358281 | E36: ='Proyeksi 24 Bulan'!$AC$123/1000000 -> 336.27401 | F36: ='Proyeksi 24 Bulan'!$AC$186/1000000 -> 1170.2409 | G36: =CHOOSE(Asumsi!$D$5,D36,E36,F36) -> 336.27401
B37: EBITDA — Bulan 0 (pra-peluncuran) | C37: Rp juta | D37: ='Proyeksi 24 Bulan'!$C$73/1000000 -> -474.72608 | E37: ='Proyeksi 24 Bulan'!$C$136/1000000 -> -474.28625 | F37: ='Proyeksi 24 Bulan'!$C$199/1000000 -> -474.08853 | G37: =CHOOSE(Asumsi!$D$5,D37,E37,F37) -> -474.28625 | H37: biaya sekali + tim & infra pra-launch
B38: EBITDA — Tahun 1 | C38: Rp juta | D38: ='Proyeksi 24 Bulan'!$AB$73/1000000 -> -1406.7523 | E38: ='Proyeksi 24 Bulan'!$AB$136/1000000 -> -1301.2929 | F38: ='Proyeksi 24 Bulan'!$AB$199/1000000 -> -1052.3702 | G38: =CHOOSE(Asumsi!$D$5,D38,E38,F38) -> -1301.2929 | H38: pra-pajak
B39: EBITDA — Tahun 2 | C39: Rp juta | D39: ='Proyeksi 24 Bulan'!$AC$73/1000000 -> -2019.0272 | E39: ='Proyeksi 24 Bulan'!$AC$136/1000000 -> -1665.3949 | F39: ='Proyeksi 24 Bulan'!$AC$199/1000000 -> -831.428 | G39: =CHOOSE(Asumsi!$D$5,D39,E39,F39) -> -1665.3949
B40: EBITDA — Bulan 24 | C40: Rp juta | D40: ='Proyeksi 24 Bulan'!$AA$73/1000000 -> -166.62315 | E40: ='Proyeksi 24 Bulan'!$AA$136/1000000 -> -127.4246 | F40: ='Proyeksi 24 Bulan'!$AA$199/1000000 -> -22.977487 | G40: =CHOOSE(Asumsi!$D$5,D40,E40,F40) -> -127.4246
B41: Puncak kebutuhan kas (peak cash burn) | C41: Rp juta | D41: =MAX(0,-MIN('Proyeksi 24 Bulan'!$C$76:$AA$76))/1000000 -> 3916.8524 | E41: =MAX(0,-MIN('Proyeksi 24 Bulan'!$C$139:$AA$139))/1000000 -> 3513.2508 | F41: =MAX(0,-MIN('Proyeksi 24 Bulan'!$C$202:$AA$202))/1000000 -> 2576.6759 | G41: =CHOOSE(Asumsi!$D$5,D41,E41,F41) -> 3513.2508 | H41: titik terendah kas kumulatif B0–B24 (sebelum buffer)
...

Sheet Asumsi
A1: Asumsi & Input Model — JastipKita
A2: Semua angka model berasal dari sel di sheet ini. Kolom Konservatif/Dasar/Optimis dapat diubah; kolom Aktif mengikuti pemilih skenario.
B4: Pemilih skenario aktif → | D4: Dasar | F4: Legenda: | G4: Biru = input | H4: Hitam = rumus
B5: Indeks skenario aktif (1/2/3) | D5: =MATCH(D4,$D$8:$F$8,0) -> 2 | G5: Hijau = tautan antar-sheet | H5: Kuning = asumsi kunci / pemilih
B6: Status: SUMBER = dari repo/URL (lihat sheet Sumber) · ASUMSI = belum ada data · USULAN = proposal launch plan yang belum disetujui owner · CEK = pemeriksaan otomatis.
A8: ID | B8: Parameter | C8: Satuan | D8: Konservatif | E8: Dasar | F8: Optimis | G8: Aktif | H8: Status | I8: Sumber / catatan
A9: 1. Pengaturan model
A10: P001 | B10: Bulan pertama soft launch (Bulan 1) | C10: tanggal | D10: 46419 | E10: 46419 | F10: 46419 | G10: =INDEX(D10:F10,$D$5) -> 46419 | H10: ASUMSI | I10: launch-plan §1/§9: soft launch = minggu ke-7 setelah dogfood. Semua gerbang P0 masih BELUM per 2026-09-28 (launch-checklist) → diasumsikan PT/NIB, PSE, kontrak Xendit & beta selesai ±4 bulan.
A11: P002 | B11: Bulan biaya pra-peluncuran yang dibebankan di Bulan 0 | C11: bulan | D11: 3 | E11: 3 | F11: 3 | G11: =INDEX(D11:F11,$D$5) -> 3 | H11: ASUMSI | I11: SDM inti + infrastruktur beta (fase 0–1B launch plan) sebelum Bulan 1.
A12: P003 | B12: Kurs USD/IDR untuk biaya dalam USD | C12: Rp/USD | D12: 17917 | E12: 17917 | F12: 17917 | G12: =INDEX(D12:F12,$D$5) -> 17917 | H12: SUMBER | I12: JISDOR 25–27 Sep 2026 — docs/research/01-customs-tax-indonesia.md §4.
A13: P004 | B13: Lag penerimaan fee platform (0 = bulan yang sama, 1 = bulan berikutnya) | C13: bulan | D13: 1 | E13: 1 | F13: 1 | G13: =INDEX(D13:F13,$D$5) -> 1 | H13: ASUMSI | I13: Fee diambil saat release setelah BUYER_CONFIRMED (research 02 §5/§10; ledger COMPLETION_RELEASE di docs/04-payments-ledger.md). Siklus trip + serah terima ±2–5 minggu.
A14: 2. Konfigurasi harga platform — packages/core/src/config/business-config.defaults.json (v1)
A15: P005 | B15: Platform fee — tarif | C15: % nilai barang | D15: 0.05 | E15: 0.05 | F15: 0.05 | G15: =INDEX(D15:F15,$D$5) -> 0.05 | H15: SUMBER | I15: pricing.platform_fee.rateBps = 500.
A16: P006 | B16: Platform fee — minimum | C16: Rp | D16: 10000 | E16: 10000 | F16: 10000 | G16: =INDEX(D16:F16,$D$5) -> 10000 | H16: SUMBER | I16: pricing.platform_fee.minIdr.
A17: P007 | B17: Platform fee — maksimum | C17: Rp | D17: 750000 | E17: 750000 | F17: 750000 | G17: =INDEX(D17:F17,$D$5) -> 750000 | H17: SUMBER | I17: pricing.platform_fee.maxIdr.
A18: P008 | B18: JastipKita Protection — tarif | C18: % nilai barang | D18: 0.015 | E18: 0.015 | F18: 0.015 | G18: =INDEX(D18:F18,$D$5) -> 0.015 | H18: SUMBER | I18: pricing.protection_fee.rateBps = 150. Belum ada mitra asuransi (INSURANCE_PROVIDER=mock; launch-checklist L9).
A19: P009 | B19: Protection fee — minimum | C19: Rp | D19: 5000 | E19: 5000 | F19: 5000 | G19: =INDEX(D19:F19,$D$5) -> 5000 | H19: SUMBER | I19: pricing.protection_fee.minIdr.
A20: P010 | B20: Protection fee — maksimum | C20: Rp | D20: 300000 | E20: 300000 | F20: 300000 | G20: =INDEX(D20:F20,$D$5) -> 300000 | H20: SUMBER | I20: pricing.protection_fee.maxIdr.
A21: P011 | B21: PPN atas layanan — tarif | C21: % | D21: 0.12 | E21: 0.12 | F21: 0.12 | G21: =INDEX(D21:F21,$D$5) -> 0.12 | H21: SUMBER | I21: pricing.service_tax.rate (berlaku atas PLATFORM_FEE + PROTECTION_FEE).
A22: P012 | B22: PPN atas layanan — faktor DPP (11/12) | C22: faktor | D22: 0.916667 | E22: 0.916667 | F22: 0.916667 | G22: =INDEX(D22:F22,$D$5) -> 0.916667 | H22: SUMBER | I22: pricing.service_tax.dppFactor; PMK 131/2024.
A23: P013 | B23: PPN layanan dipungut? (1 = ya/PKP, 0 = tidak) | C23: 1/0 | D23: 1 | E23: 1 | F23: 1 | G23: =INDEX(D23:F23,$D$5) -> 1 | H23: SUMBER | I23: Config enabled=true. Hanya boleh dipungut bila PT sudah PKP (launch-checklist L8); wajib PKP bila omzet > Rp4,8 M/tahun (research 05 §4). Pass-through — tidak mengubah pendapatan bersih.
A24: P014 | B24: Traveler fee — minimum | C24: Rp | D24: 25000 | E24: 25000 | F24: 25000 | G24: =INDEX(D24:F24,$D$5) -> 25000 | H24: SUMBER | I24: pricing.traveler_fee_bounds.minIdr.
A25: P015 | B25: Traveler fee — maksimum (% nilai barang) | C25: % | D25: 0.3 | E25: 0.3 | F25: 0.3 | G25: =INDEX(D25:F25,$D$5) -> 0.3 | H25: SUMBER | I25: pricing.traveler_fee_bounds.maxRateBps = 3000.
A26: P016 | B26: Nilai barang minimum per transaksi | C26: Rp | D26: 100000 | E26: 100000 | F26: 100000 | G26: =INDEX(D26:F26,$D$5) -> 100000 | H26: SUMBER | I26: pricing.minimum_transaction.minItemValueIdr.
A27: P017 | B27: Markup kurs (informasi — BUKAN pendapatan) | C27: % | D27: 0.015 | E27: 0.015 | F27: 0.015 | G27: =INDEX(D27:F27,$D$5) -> 0.015 | H27: SUMBER | I27: pricing.fx_markup.defaultBps = 150 (KRW 200). Selisih dana barang dikembalikan ke pembeli saat COMPLETION_RELEASE (docs/04-payments-ledger.md §3) → tidak dihitung sebagai pendapatan.
A28: 3. Biaya pembayaran yang DIBEBANKAN ke pembeli — config pricing.payment_fees (bearer BUYER, gross-up di pricing/index.ts)
A29: P018 | B29: VA — biaya tetap dibebankan | C29: Rp | D29: 4500 | E29: 4500 | F29: 4500 | G29: =INDEX(D29:F29,$D$5) -> 4500 | H29: SUMBER | I29: pricing.payment_fees.channels.VA.fixedIdr (bertanda asumsi di config sampai kontrak Xendit).
A30: P019 | B30: VA — tarif persen dibebankan | C30: % | D30: 0 | E30: 0 | F30: 0 | G30: =INDEX(D30:F30,$D$5) -> 0 | H30: SUMBER | I30: VA.rateBps = 0.
A31: P020 | B31: QRIS — biaya tetap dibebankan | C31: Rp | D31: 0 | E31: 0 | F31: 0 | G31: =INDEX(D31:F31,$D$5) -> 0 | H31: SUMBER | I31: QRIS.fixedIdr = 0.
A32: P021 | B32: QRIS — tarif persen dibebankan | C32: % | D32: 0.007 | E32: 0.007 | F32: 0.007 | G32: =INDEX(D32:F32,$D$5) -> 0.007 | H32: SUMBER | I32: QRIS.rateBps = 70.
A33: P022 | B33: E-wallet — biaya tetap dibebankan | C33: Rp | D33: 0 | E33: 0 | F33: 0 | G33: =INDEX(D33:F33,$D$5) -> 0 | H33: SUMBER | I33: EWALLET.fixedIdr = 0.
A34: P023 | B34: E-wallet — tarif persen dibebankan | C34: % | D34: 0.015 | E34: 0.015 | F34: 0.015 | G34: =INDEX(D34:F34,$D$5) -> 0.015 | H34: SUMBER | I34: EWALLET.rateBps = 150.
A35: P024 | B35: Kartu — biaya tetap dibebankan | C35: Rp | D35: 2000 | E35: 2000 | F35: 2000 | G35: =INDEX(D35:F35,$D$5) -> 2000 | H35: SUMBER | I35: CARD.fixedIdr = 2000.
A36: P025 | B36: Kartu — tarif persen dibebankan | C36: % | D36: 0.029 | E36: 0.029 | F36: 0.029 | G36: =INDEX(D36:F36,$D$5) -> 0.029 | H36: SUMBER | I36: CARD.rateBps = 290.
A37: 4. Biaya Xendit — tarif publik (bukan kontrak). research 02 §8 (2026-09-27) + xendit.co/en-id/pricing diverifikasi ulang 2026-10-04
A38: P026 | B38: VA — fee metode | C38: Rp | D38: 9000 | E38: 9000 | F38: 9000 | G38: =INDEX(D38:F38,$D$5) -> 9000 | H38: SUMBER | I38: Xendit pricing: VA Rp9.000 + processing Rp4.000 (exclusive of taxes).
A39: P027 | B39: Processing fee Xendit per transaksi (semua metode & payout) | C39: Rp | D39: 4000 | E39: 4000 | F39: 4000 | G39: =INDEX(D39:F39,$D$5) -> 4000 | H39: SUMBER | I39: Xendit pricing (2026-10-04).
A40: P028 | B40: QRIS — fee metode (sudah termasuk PPN) | C40: % | D40: 0.007 | E40: 0.007 | F40: 0.007 | G40: =INDEX(D40:F40,$D$5) -> 0.007 | H40: SUMBER | I40: Xendit pricing: 0,70% inclusive of VAT + Rp4.000.
A41: P029 | B41: E-wallet — fee metode (rata-rata tertimbang) | C41: % | D41: 0.035 | E41: 0.03 | F41: 0.025 | G41: =INDEX(D41:F41,$D$5) -> 0.03 | H41: ASUMSI | I41: Dalam rentang publik: OVO 3,00–5,50%, DANA 2,00–3,50% (berubah dari 3,00–3,50% di research 02), ShopeePay 2,50–3,60%, GoPay 3,00–5,00% + Rp4.000.
A42: P030 | B42: Kartu — fee persen | C42: % | D42: 0.029 | E42: 0.029 | F42: 0.029 | G42: =INDEX(D42:F42,$D$5) -> 0.029 | H42: SUMBER | I42: Visa/MC/JCB 2,90% + Rp2.000 + Rp4.000.
...

Sheet Unit Economics
A1: Unit Economics — satu transaksi melalui 11 baris harga
A2: Kolom C–E: transaksi representatif tiap skenario (asumsi skenario masing-masing). Kolom F–H: tiga ukuran keranjang dengan asumsi skenario aktif. Rumus mengikuti packages/core/src/pricing (clamp, gross-up kanal bayar, PPN DPP 11/12, CEIL_1000 bea).
A3: ="Skenario aktif: "&Asumsi!$D$4 -> Skenario aktif: Dasar
B4: Baris / komponen | C4: Konservatif (rep.) | D4: Dasar (rep.) | E4: Optimis (rep.) | F4: Aktif — Rp1 jt | G4: Aktif — Rp2,5 jt | H4: Aktif — Rp5 jt | I4: Bucket ledger | J4: Sifat bagi platform / catatan
B5: Indeks skenario (1 K · 2 D · 3 O) | C5: 1 | D5: 2 | E5: 3 | F5: =Asumsi!$D$5 -> 2 | G5: =Asumsi!$D$5 -> 2 | H5: =Asumsi!$D$5 -> 2
B6: Nilai barang (Rp) | C6: =INDEX(Asumsi!$D$58:$F$58,C$5) -> 1500000 | D6: =INDEX(Asumsi!$D$58:$F$58,D$5) -> 2000000 | E6: =INDEX(Asumsi!$D$58:$F$58,E$5) -> 2500000 | F6: 1000000 | G6: 2500000 | H6: 5000000
A7: A. Rincian 11 baris harga per transaksi (dibayar pembeli) — urutan docs/00-domain-model.md §10
B8: 1. ITEM_PRICE — Harga Barang | C8: =C6 -> 1500000 | D8: =D6 -> 2000000 | E8: =E6 -> 2500000 | F8: =F6 -> 1000000 | G8: =G6 -> 2500000 | H8: =H6 -> 5000000 | I8: PRODUCT_FUND | J8: Pass-through → traveler (penggantian harga beli)
B9: 2. TRAVELER_FEE — Traveler Fee | C9: =MAX(C81,MIN(ROUND(C8*C80,0),ROUNDDOWN(C8*C82,0))) -> 150000 | D9: =MAX(D81,MIN(ROUND(D8*D80,0),ROUNDDOWN(D8*D82,0))) -> 200000 | E9: =MAX(E81,MIN(ROUND(E8*E80,0),ROUNDDOWN(E8*E82,0))) -> 250000 | F9: =MAX(F81,MIN(ROUND(F8*F80,0),ROUNDDOWN(F8*F82,0))) -> 100000 | G9: =MAX(G81,MIN(ROUND(G8*G80,0),ROUNDDOWN(G8*G82,0))) -> 250000 | H9: =MAX(H81,MIN(ROUND(H8*H80,0),ROUNDDOWN(H8*H82,0))) -> 500000 | I9: TRAVELER_EARNING | J9: Pass-through → penghasilan traveler
B10: 3. CUSTOMS_DUTY — Bea Masuk (estimasi) | C10: =CEILING(C8*C83,1000) -> 150000 | D10: =CEILING(D8*D83,1000) -> 200000 | E10: =CEILING(E8*E83,1000) -> 250000 | F10: =CEILING(F8*F83,1000) -> 100000 | G10: =CEILING(G8*G83,1000) -> 250000 | H10: =CEILING(H8*H83,1000) -> 500000 | I10: CUSTOMS_RESERVE | J10: Pass-through → DJBC (dibayar traveler)
B11: 4. IMPORT_TAX — PPN impor + PPh 22 (estimasi) | C11: =CEILING((C8+C10)*C84*C85,1000)+CEILING((C8+C10)*C86,1000) -> 265000 | D11: =CEILING((D8+D10)*D84*D85,1000)+CEILING((D8+D10)*D86,1000) -> 353000 | E11: =CEILING((E8+E10)*E84*E85,1000)+CEILING((E8+E10)*E86,1000) -> 441000 | F11: =CEILING((F8+F10)*F84*F85,1000)+CEILING((F8+F10)*F86,1000) -> 177000 | G11: =CEILING((G8+G10)*G84*G85,1000)+CEILING((G8+G10)*G86,1000) -> 441000 | H11: =CEILING((H8+H10)*H84*H85,1000)+CEILING((H8+H10)*H86,1000) -> 881000 | I11: CUSTOMS_RESERVE | J11: Pass-through → DJBC (dibayar traveler)
B12: 5. PROTECTION_FEE — JastipKita Protection | C12: =MIN(C89,MAX(C88,ROUND(C8*C87,0))) -> 22500 | D12: =MIN(D89,MAX(D88,ROUND(D8*D87,0))) -> 30000 | E12: =MIN(E89,MAX(E88,ROUND(E8*E87,0))) -> 37500 | F12: =MIN(F89,MAX(F88,ROUND(F8*F87,0))) -> 15000 | G12: =MIN(G89,MAX(G88,ROUND(G8*G87,0))) -> 37500 | H12: =MIN(H89,MAX(H88,ROUND(H8*H87,0))) -> 75000 | I12: PLATFORM_REVENUE | J12: Pendapatan platform (menanggung klaim)
B13: 6. PLATFORM_FEE — Platform Fee | C13: =MIN(C92,MAX(C91,ROUND(C8*C90,0))) -> 75000 | D13: =MIN(D92,MAX(D91,ROUND(D8*D90,0))) -> 100000 | E13: =MIN(E92,MAX(E91,ROUND(E8*E90,0))) -> 125000 | F13: =MIN(F92,MAX(F91,ROUND(F8*F90,0))) -> 50000 | G13: =MIN(G92,MAX(G91,ROUND(G8*G90,0))) -> 125000 | H13: =MIN(H92,MAX(H91,ROUND(H8*H90,0))) -> 250000 | I13: PLATFORM_REVENUE | J13: Pendapatan platform
B14: 7. SERVICE_TAX — PPN atas layanan | C14: =C95*ROUND((C12+C13)*C94*C93,0) -> 10725 | D14: =D95*ROUND((D12+D13)*D94*D93,0) -> 14300 | E14: =E95*ROUND((E12+E13)*E94*E93,0) -> 17875 | F14: =F95*ROUND((F12+F13)*F94*F93,0) -> 7150 | G14: =G95*ROUND((G12+G13)*G94*G93,0) -> 17875 | H14: =H95*ROUND((H12+H13)*H94*H93,0) -> 35750 | I14: TAX_PAYABLE | J14: Pass-through → kas negara (hanya bila PKP)
B15: 8. PAYMENT_FEE — rata-rata tertimbang bauran kanal | C15: =C33 -> 15092.68 | D15: =D33 -> 22833.65 | E15: =E33 -> 32611.38 | F15: =F33 -> 12648.45 | G15: =G33 -> 27926.15 | H15: =H33 -> 53388.95 | I15: PAYMENT_FEE | J15: Pass-through → Xendit (kekurangan disubsidi platform)
B16: 9. DISCOUNT — Diskon promo (negatif) | C16: 0 | D16: 0 | E16: 0 | F16: 0 | G16: 0 | H16: 0 | I16: PROMOTION_CREDIT | J16: Transaksi representatif tanpa promo; promo dihitung teramortisasi di bagian C
B17: 10. REFERRAL_CREDIT — JastipKita Credit (negatif) | C17: 0 | D17: 0 | E17: 0 | F17: 0 | G17: 0 | H17: 0 | I17: PROMOTION_CREDIT | J17: Idem — credit referral teramortisasi di bagian C
B18: 11. TOTAL — Total Landed Cost (= GMV per transaksi) | C18: =SUM(C8:C14)+C15+C16+C17 -> 2188317.7 | D18: =SUM(D8:D14)+D15+D16+D17 -> 2920133.6 | E18: =SUM(E8:E14)+E15+E16+E17 -> 3653986.4 | F18: =SUM(F8:F14)+F15+F16+F17 -> 1461798.4 | G18: =SUM(G8:G14)+G15+G16+G17 -> 3649301.1 | H18: =SUM(H8:H14)+H15+H16+H17 -> 7295139 | I18: — | J18: Kas dibayar pembeli
A19: A2. Biaya kanal pembayaran — dibebankan ke pembeli (config) vs biaya Xendit (tarif publik); lihat launch-checklist B4
B20: Dasar sebelum biaya bayar (P = baris 1–7 + 9 + 10) | C20: =SUM(C8:C14)+C16+C17 -> 2173225 | D20: =SUM(D8:D14)+D16+D17 -> 2897300 | E20: =SUM(E8:E14)+E16+E17 -> 3621375 | F20: =SUM(F8:F14)+F16+F17 -> 1449150 | G20: =SUM(G8:G14)+G16+G17 -> 3621375 | H20: =SUM(H8:H14)+H16+H17 -> 7241750
B21: VA — dibebankan ke pembeli | C21: =IF(C20>0,ROUNDUP(ROUND((C20+C96)/(1-C97),6),0)-C20,0) -> 4500 | D21: =IF(D20>0,ROUNDUP(ROUND((D20+D96)/(1-D97),6),0)-D20,0) -> 4500 | E21: =IF(E20>0,ROUNDUP(ROUND((E20+E96)/(1-E97),6),0)-E20,0) -> 4500 | F21: =IF(F20>0,ROUNDUP(ROUND((F20+F96)/(1-F97),6),0)-F20,0) -> 4500 | G21: =IF(G20>0,ROUNDUP(ROUND((G20+G96)/(1-G97),6),0)-G20,0) -> 4500 | H21: =IF(H20>0,ROUNDUP(ROUND((H20+H96)/(1-H97),6),0)-H20,0) -> 4500 | J21: config VA Rp4.500
B22: VA — biaya Xendit ((Rp9.000 + Rp4.000) × 1,11) | C22: =ROUND((C104+C105)*(1+C110),0) -> 14430 | D22: =ROUND((D104+D105)*(1+D110),0) -> 14430 | E22: =ROUND((E104+E105)*(1+E110),0) -> 14430 | F22: =ROUND((F104+F105)*(1+F110),0) -> 14430 | G22: =ROUND((G104+G105)*(1+G110),0) -> 14430 | H22: =ROUND((H104+H105)*(1+H110),0) -> 14430 | J22: tarif publik
B23: VA — subsidi platform | C23: =C22-C21 -> 9930 | D23: =D22-D21 -> 9930 | E23: =E22-E21 -> 9930 | F23: =F22-F21 -> 9930 | G23: =G22-G21 -> 9930 | H23: =H22-H21 -> 9930 | J23: B4: ±Rp9.930
B24: QRIS — dibebankan ke pembeli | C24: =IF(C20>0,ROUNDUP(ROUND((C20+C98)/(1-C99),6),0)-C20,0) -> 15320 | D24: =IF(D20>0,ROUNDUP(ROUND((D20+D98)/(1-D99),6),0)-D20,0) -> 20425 | E24: =IF(E20>0,ROUNDUP(ROUND((E20+E98)/(1-E99),6),0)-E20,0) -> 25529 | F24: =IF(F20>0,ROUNDUP(ROUND((F20+F98)/(1-F99),6),0)-F20,0) -> 10216 | G24: =IF(G20>0,ROUNDUP(ROUND((G20+G98)/(1-G99),6),0)-G20,0) -> 25529 | H24: =IF(H20>0,ROUNDUP(ROUND((H20+H98)/(1-H99),6),0)-H20,0) -> 51050 | J24: config 0,70% gross-up
B25: QRIS — biaya Xendit (0,70% incl. PPN + Rp4.000 × 1,11) | C25: =ROUND((C20+C24)*C106+C105*(1+C110),0) -> 19760 | D25: =ROUND((D20+D24)*D106+D105*(1+D110),0) -> 24864 | E25: =ROUND((E20+E24)*E106+E105*(1+E110),0) -> 29968 | F25: =ROUND((F20+F24)*F106+F105*(1+F110),0) -> 14656 | G25: =ROUND((G20+G24)*G106+G105*(1+G110),0) -> 29968 | H25: =ROUND((H20+H24)*H106+H105*(1+H110),0) -> 55490
B26: QRIS — subsidi platform | C26: =C25-C24 -> 4440 | D26: =D25-D24 -> 4439 | E26: =E25-E24 -> 4439 | F26: =F25-F24 -> 4440 | G26: =G25-G24 -> 4439 | H26: =H25-H24 -> 4440
B27: E-wallet — dibebankan ke pembeli | C27: =IF(C20>0,ROUNDUP(ROUND((C20+C100)/(1-C101),6),0)-C20,0) -> 33095 | D27: =IF(D20>0,ROUNDUP(ROUND((D20+D100)/(1-D101),6),0)-D20,0) -> 44122 | E27: =IF(E20>0,ROUNDUP(ROUND((E20+E100)/(1-E101),6),0)-E20,0) -> 55148 | F27: =IF(F20>0,ROUNDUP(ROUND((F20+F100)/(1-F101),6),0)-F20,0) -> 22069 | G27: =IF(G20>0,ROUNDUP(ROUND((G20+G100)/(1-G101),6),0)-G20,0) -> 55148 | H27: =IF(H20>0,ROUNDUP(ROUND((H20+H100)/(1-H101),6),0)-H20,0) -> 110281 | J27: config 1,50% gross-up
B28: E-wallet — biaya Xendit ((tarif × TOTAL + Rp4.000) × 1,11) | C28: =ROUND(((C20+C27)*C107+C105)*(1+C110),0) -> 90156 | D28: =ROUND(((D20+D27)*D107+D105)*(1+D110),0) -> 102389 | E28: =ROUND(((E20+E27)*E107+E105)*(1+E110),0) -> 106464 | F28: =ROUND(((F20+F27)*F107+F105)*(1+F110),0) -> 53432 | G28: =ROUND(((G20+G27)*G107+G105)*(1+G110),0) -> 126868 | H28: =ROUND(((H20+H27)*H107+H105)*(1+H110),0) -> 249263
B29: E-wallet — subsidi platform | C29: =C28-C27 -> 57061 | D29: =D28-D27 -> 58267 | E29: =E28-E27 -> 51316 | F29: =F28-F27 -> 31363 | G29: =G28-G27 -> 71720 | H29: =H28-H27 -> 138982
B30: Kartu — dibebankan ke pembeli | C30: =IF(C20>0,ROUNDUP(ROUND((C20+C102)/(1-C103),6),0)-C20,0) -> 66966 | D30: =IF(D20>0,ROUNDUP(ROUND((D20+D102)/(1-D103),6),0)-D20,0) -> 88591 | E30: =IF(E20>0,ROUNDUP(ROUND((E20+E102)/(1-E103),6),0)-E20,0) -> 110217 | F30: =IF(F20>0,ROUNDUP(ROUND((F20+F102)/(1-F103),6),0)-F20,0) -> 45341 | G30: =IF(G20>0,ROUNDUP(ROUND((G20+G102)/(1-G103),6),0)-G20,0) -> 110217 | H30: =IF(H20>0,ROUNDUP(ROUND((H20+H102)/(1-H103),6),0)-H20,0) -> 218343 | J30: config Rp2.000 + 2,90% gross-up
B31: Kartu — biaya Xendit ((2,90% × TOTAL + Rp2.000 + Rp4.000) × 1,11) | C31: =ROUND(((C20+C30)*C108+C109+C105)*(1+C110),0) -> 78772 | D31: =ROUND(((D20+D30)*D108+D109+D105)*(1+D110),0) -> 102776 | E31: =ROUND(((E20+E30)*E108+E109+E105)*(1+E110),0) -> 126780 | F31: =ROUND(((F20+F30)*F108+F109+F105)*(1+F110),0) -> 54768 | G31: =ROUND(((G20+G30)*G108+G109+G105)*(1+G110),0) -> 126780 | H31: =ROUND(((H20+H30)*H108+H109+H105)*(1+H110),0) -> 246800
B32: Kartu — subsidi platform | C32: =C31-C30 -> 11806 | D32: =D31-D30 -> 14185 | E32: =E31-E30 -> 16563 | F32: =F31-F30 -> 9427 | G32: =G31-G30 -> 16563 | H32: =H31-H30 -> 28457
B33: Rata-rata dibebankan ke pembeli (bauran) | C33: =C114*C21+C115*C24+C116*C27+C117*C30 -> 15092.68 | D33: =D114*D21+D115*D24+D116*D27+D117*D30 -> 22833.65 | E33: =E114*E21+E115*E24+E116*E27+E117*E30 -> 32611.38 | F33: =F114*F21+F115*F24+F116*F27+F117*F30 -> 12648.45 | G33: =G114*G21+G115*G24+G116*G27+G117*G30 -> 27926.15 | H33: =H114*H21+H115*H24+H116*H27+H117*H30 -> 53388.95
B34: Rata-rata biaya Xendit (bauran) | C34: =C114*C22+C115*C25+C116*C28+C117*C31 -> 29730.48 | D34: =D114*D22+D115*D25+D116*D28+D117*D31 -> 39066.95 | E34: =E114*E22+E115*E25+E116*E28+E117*E31 -> 49139.52 | F34: =F114*F22+F115*F25+F116*F28+F117*F31 -> 24370.6 | G34: =G114*G22+G115*G25+G116*G28+G117*G31 -> 46415.2 | H34: =H114*H22+H115*H25+H116*H28+H117*H31 -> 83156.95
B35: Rata-rata subsidi platform per transaksi (bauran) | C35: =C34-C33 -> 14637.8 | D35: =D34-D33 -> 16233.3 | E35: =E34-E33 -> 16528.14 | F35: =F34-F33 -> 11722.15 | G35: =G34-G33 -> 18489.05 | H35: =H34-H33 -> 29768
A36: B. Alokasi dana — siapa menerima apa (ledger COMPLETION_RELEASE, docs/04-payments-ledger.md)
B37: Traveler — penggantian harga barang (pass-through) | C37: =C8 -> 1500000 | D37: =D8 -> 2000000 | E37: =E8 -> 2500000 | F37: =F8 -> 1000000 | G37: =G8 -> 2500000 | H37: =H8 -> 5000000
B38: Traveler — traveler fee (penghasilan traveler) | C38: =C9 -> 150000 | D38: =D9 -> 200000 | E38: =E9 -> 250000 | F38: =F9 -> 100000 | G38: =G9 -> 250000 | H38: =H9 -> 500000
B39: DJBC — bea masuk + pajak impor via traveler (pass-through) | C39: =C10+C11 -> 415000 | D39: =D10+D11 -> 553000 | E39: =E10+E11 -> 691000 | F39: =F10+F11 -> 277000 | G39: =G10+G11 -> 691000 | H39: =H10+H11 -> 1381000
B40: Negara — PPN atas layanan (pass-through) | C40: =C14 -> 10725 | D40: =D14 -> 14300 | E40: =E14 -> 17875 | F40: =F14 -> 7150 | G40: =G14 -> 17875 | H40: =H14 -> 35750
...

Sheet Proyeksi 24 Bulan
A1: Proyeksi 24 Bulan sejak soft launch (Bulan 0 = pra-peluncuran)
A2: Tiga blok skenario dihitung serentak (Konservatif, Dasar, Optimis); ringkasan di atas mengikuti skenario aktif. Satuan Rp kecuali disebut. Kas = kas perusahaan saja — dana escrow pembeli di saldo Xendit bukan kas perusahaan.
A3: ="Skenario aktif: "&Asumsi!$D$4 -> Skenario aktif: Dasar
A5: Bulan ke- | B5: Satuan | C5: 0 | D5: 1 | E5: 2 | F5: 3 | G5: 4 | H5: 5 | I5: 6 | J5: 7 | K5: 8 | L5: 9 | M5: 10 | N5: 11 | O5: 12 | P5: 13 | Q5: 14 | R5: 15 | S5: 16 | T5: 17 | U5: 18 | V5: 19 | W5: 20 | X5: 21 | Y5: 22 | Z5: 23 | AA5: 24 | AB5: Tahun 1 (B1–B12) | AC5: Tahun 2 (B13–B24) | AD5: Total B0–B24
A6: Periode | C6: Pra-launch | D6: =EDATE(Asumsi!$G$10,D$5-1) -> 46419 | E6: =EDATE(Asumsi!$G$10,E$5-1) -> 46447 | F6: =EDATE(Asumsi!$G$10,F$5-1) -> 46478 | G6: =EDATE(Asumsi!$G$10,G$5-1) -> 46508 | H6: =EDATE(Asumsi!$G$10,H$5-1) -> 46539 | I6: =EDATE(Asumsi!$G$10,I$5-1) -> 46569 | J6: =EDATE(Asumsi!$G$10,J$5-1) -> 46600 | K6: =EDATE(Asumsi!$G$10,K$5-1) -> 46631 | ... AA6: =EDATE(Asumsi!$G$10,AA$5-1) -> 47119
A7: RINGKASAN SKENARIO AKTIF (CHOOSE dari blok di bawah)
A8: Transaksi selesai — skenario aktif | B8: trx | C8: =CHOOSE(Asumsi!$D$5,C38,C101,C164) -> 0 | D8: =CHOOSE(Asumsi!$D$5,D38,D101,D164) -> 34.1145 | E8: =CHOOSE(Asumsi!$D$5,E38,E101,E164) -> 48.90942 | F8: =CHOOSE(Asumsi!$D$5,F38,F101,F164) -> 64.405303 | G8: =CHOOSE(Asumsi!$D$5,G38,G101,G164) -> 80.677532 | H8: =CHOOSE(Asumsi!$D$5,H38,H101,H164) -> 97.806747 | I8: =CHOOSE(Asumsi!$D$5,I38,I101,I164) -> 115.8793 | J8: =CHOOSE(Asumsi!$D$5,J38,J101,J164) -> 134.98773 | ... AD8: =CHOOSE(Asumsi!$D$5,AD38,AD101,AD164) -> 6812.5153
A9: GMV bruto — skenario aktif | B9: Rp | C9: =CHOOSE(Asumsi!$D$5,C41,C104,C167) -> 0 | D9: =CHOOSE(Asumsi!$D$5,D41,D104,D167) -> 99618899 | E9: =CHOOSE(Asumsi!$D$5,E41,E104,E167) -> 1.4282204e+08 | F9: =CHOOSE(Asumsi!$D$5,F41,F104,F167) -> 1.8807209e+08 | G9: =CHOOSE(Asumsi!$D$5,G41,G104,G167) -> 2.3558918e+08 | H9: =CHOOSE(Asumsi!$D$5,H41,H104,H167) -> 2.8560877e+08 | I9: =CHOOSE(Asumsi!$D$5,I41,I104,I167) -> 3.3838304e+08 | J9: =CHOOSE(Asumsi!$D$5,J41,J104,J167) -> 3.9418222e+08 | ... AD9: =CHOOSE(Asumsi!$D$5,AD41,AD104,AD167) -> 1.9893455e+10
A10: Pendapatan bersih — skenario aktif | B10: Rp | C10: =CHOOSE(Asumsi!$D$5,C47,C110,C173) -> 0 | D10: =CHOOSE(Asumsi!$D$5,D47,D110,D173) -> 3927823.5 | E10: =CHOOSE(Asumsi!$D$5,E47,E110,E173) -> 5650747.3 | F10: =CHOOSE(Asumsi!$D$5,F47,F110,F173) -> 7449831.6 | G10: =CHOOSE(Asumsi!$D$5,G47,G110,G173) -> 9334908.2 | H10: =CHOOSE(Asumsi!$D$5,H47,H110,H173) -> 11311063 | I10: =CHOOSE(Asumsi!$D$5,I47,I110,I173) -> 13393019 | J10: =CHOOSE(Asumsi!$D$5,J47,J110,J173) -> 16672066 | ... AD10: =CHOOSE(Asumsi!$D$5,AD47,AD110,AD173) -> 8.345434e+08
A11: Margin kontribusi — skenario aktif | B11: Rp | C11: =CHOOSE(Asumsi!$D$5,C60,C123,C186) -> -1090756.4 | D11: =CHOOSE(Asumsi!$D$5,D60,D123,D186) -> 1336870.8 | E11: =CHOOSE(Asumsi!$D$5,E60,E123,E186) -> 2318070.4 | F11: =CHOOSE(Asumsi!$D$5,F60,F123,F186) -> 3335273.8 | G11: =CHOOSE(Asumsi!$D$5,G60,G123,G186) -> 3129729.4 | H11: =CHOOSE(Asumsi!$D$5,H60,H123,H186) -> 4230549.9 | I11: =CHOOSE(Asumsi!$D$5,I60,I123,I186) -> 5385485.3 | J11: =CHOOSE(Asumsi!$D$5,J60,J123,J186) -> 7681457.7 | ... AD11: =CHOOSE(Asumsi!$D$5,AD60,AD123,AD186) -> 4.2455927e+08
A12: Biaya akuisisi & tetap — skenario aktif | B12: Rp | C12: =CHOOSE(Asumsi!$D$5,C71,C134,C197) -> 473195491 | D12: =CHOOSE(Asumsi!$D$5,D71,D134,D197) -> 100741261 | E12: =CHOOSE(Asumsi!$D$5,E71,E134,E197) -> 100741261 | F12: =CHOOSE(Asumsi!$D$5,F71,F134,F197) -> 100741261 | G12: =CHOOSE(Asumsi!$D$5,G71,G134,G197) -> 120741261 | H12: =CHOOSE(Asumsi!$D$5,H71,H134,H197) -> 120741261 | I12: =CHOOSE(Asumsi!$D$5,I71,I134,I197) -> 120741261 | J12: =CHOOSE(Asumsi!$D$5,J71,J134,J197) -> 120741261 | ... AD12: =CHOOSE(Asumsi!$D$5,AD71,AD134,AD197) -> 3865533321
A13: EBITDA — skenario aktif | B13: Rp | C13: =CHOOSE(Asumsi!$D$5,C73,C136,C199) -> -4.7428625e+08 | D13: =CHOOSE(Asumsi!$D$5,D73,D136,D199) -> -99404390 | E13: =CHOOSE(Asumsi!$D$5,E73,E136,E199) -> -98423191 | F13: =CHOOSE(Asumsi!$D$5,F73,F136,F199) -> -97405987 | G13: =CHOOSE(Asumsi!$D$5,G73,G136,G199) -> -1.1761153e+08 | H13: =CHOOSE(Asumsi!$D$5,H73,H136,H199) -> -1.1651071e+08 | I13: =CHOOSE(Asumsi!$D$5,I73,I136,I199) -> -1.1535578e+08 | J13: =CHOOSE(Asumsi!$D$5,J73,J136,J199) -> -1.130598e+08 | ... AD13: =CHOOSE(Asumsi!$D$5,AD73,AD136,AD199) -> -3.4409741e+09
A14: Kas kumulatif — skenario aktif | B14: Rp | C14: =CHOOSE(Asumsi!$D$5,C76,C139,C202) -> -4.7428625e+08 | D14: =CHOOSE(Asumsi!$D$5,D76,D139,D202) -> -5.7761846e+08 | E14: =CHOOSE(Asumsi!$D$5,E76,E139,E202) -> -6.7776458e+08 | F14: =CHOOSE(Asumsi!$D$5,F76,F139,F202) -> -7.7696965e+08 | G14: =CHOOSE(Asumsi!$D$5,G76,G139,G202) -> -8.9646626e+08 | H14: =CHOOSE(Asumsi!$D$5,H76,H139,H202) -> -1.0149531e+09 | I14: =CHOOSE(Asumsi!$D$5,I76,I139,I202) -> -1.1323909e+09 | J14: =CHOOSE(Asumsi!$D$5,J76,J139,J202) -> -1.2487297e+09 | ... AD14: =CHOOSE(Asumsi!$D$5,AD76,AD139,AD202) -> -3.5132508e+09
A17: SKENARIO KONSERVATIF — input dari Asumsi kolom D, unit economics dari kolom C
A18: Pasokan traveler
A19: Traveler terverifikasi baru (B0 = peserta beta) | B19: orang | C19: =Asumsi!$D$74 -> 20 | D19: =Asumsi!$D$75*(1+Asumsi!$D$76)^(D$5-1) -> 10 | E19: =Asumsi!$D$75*(1+Asumsi!$D$76)^(E$5-1) -> 10.4 | F19: =Asumsi!$D$75*(1+Asumsi!$D$76)^(F$5-1) -> 10.816 | G19: =Asumsi!$D$75*(1+Asumsi!$D$76)^(G$5-1) -> 11.24864 | H19: =Asumsi!$D$75*(1+Asumsi!$D$76)^(H$5-1) -> 11.698586 | I19: =Asumsi!$D$75*(1+Asumsi!$D$76)^(I$5-1) -> 12.166529 | J19: =Asumsi!$D$75*(1+Asumsi!$D$76)^(J$5-1) -> 12.65319 | K19: =Asumsi!$D$75*(1+Asumsi!$D$76)^(K$5-1) -> 13.159318 | ... AA19: =Asumsi!$D$75*(1+Asumsi!$D$76)^(AA$5-1) -> 24.647155 | AB19: =SUM(D19:O19) -> 150.25805 | AC19: =SUM(P19:AA19) -> 240.56799 | AD19: =SUM(C19:AA19) -> 410.82604
A20: Basis traveler terverifikasi (akhir bulan) | B20: orang | C20: =C19 -> 20 | D20: =C20*(1-Asumsi!$D$77)+D19 -> 29 | E20: =D20*(1-Asumsi!$D$77)+E19 -> 37.95 | F20: =E20*(1-Asumsi!$D$77)+F19 -> 46.8685 | G20: =F20*(1-Asumsi!$D$77)+G19 -> 55.773715 | H20: =G20*(1-Asumsi!$D$77)+H19 -> 64.683615 | I20: =H20*(1-Asumsi!$D$77)+I19 -> 73.615963 | J20: =I20*(1-Asumsi!$D$77)+J19 -> 82.588355 | K20: =J20*(1-Asumsi!$D$77)+K19 -> 91.618255 | ... AA20: =Z20*(1-Asumsi!$D$77)+AA19 -> 258.20813 | AB20: =O20 -> 128.65966 | AC20: =AA20 -> 258.20813 | AD20: =AA20 -> 258.20813
A21: Traveler aktif (punya trip) | B21: orang | D21: =D20*Asumsi!$D$78 -> 8.7 | E21: =E20*Asumsi!$D$78 -> 11.385 | F21: =F20*Asumsi!$D$78 -> 14.06055 | G21: =G20*Asumsi!$D$78 -> 16.732115 | H21: =H20*Asumsi!$D$78 -> 19.405084 | I21: =I20*Asumsi!$D$78 -> 22.084789 | J21: =J20*Asumsi!$D$78 -> 24.776507 | K21: =K20*Asumsi!$D$78 -> 27.485477 | ... AA21: =AA20*Asumsi!$D$78 -> 77.462439 | AB21: =O21 -> 38.597898 | AC21: =AA21 -> 77.462439 | AD21: =AA21 -> 77.462439
A22: Kapasitas pesanan | B22: pesanan | D22: =D21*Asumsi!$D$79 -> 21.75 | E22: =E21*Asumsi!$D$79 -> 28.4625 | F22: =F21*Asumsi!$D$79 -> 35.151375 | G22: =G21*Asumsi!$D$79 -> 41.830286 | H22: =H21*Asumsi!$D$79 -> 48.512711 | I22: =I21*Asumsi!$D$79 -> 55.211972 | J22: =J21*Asumsi!$D$79 -> 61.941266 | K22: =K21*Asumsi!$D$79 -> 68.713691 | ... AA22: =AA21*Asumsi!$D$79 -> 193.6561 | AB22: =SUM(D22:O22) -> 705.47065 | AC22: =SUM(P22:AA22) -> 1762.4541 | AD22: =SUM(C22:AA22) -> 2467.9248
A23: Permintaan pembeli
A24: Pembeli baru — organik | B24: orang | D24: =Asumsi!$D$82*(1+Asumsi!$D$83)^(D$5-1) -> 20 | E24: =Asumsi!$D$82*(1+Asumsi!$D$83)^(E$5-1) -> 21 | F24: =Asumsi!$D$82*(1+Asumsi!$D$83)^(F$5-1) -> 22.05 | G24: =Asumsi!$D$82*(1+Asumsi!$D$83)^(G$5-1) -> 23.1525 | H24: =Asumsi!$D$82*(1+Asumsi!$D$83)^(H$5-1) -> 24.310125 | I24: =Asumsi!$D$82*(1+Asumsi!$D$83)^(I$5-1) -> 25.525631 | J24: =Asumsi!$D$82*(1+Asumsi!$D$83)^(J$5-1) -> 26.801913 | K24: =Asumsi!$D$82*(1+Asumsi!$D$83)^(K$5-1) -> 28.142008 | ... AA24: =Asumsi!$D$82*(1+Asumsi!$D$83)^(AA$5-1) -> 61.430475 | AB24: =SUM(D24:O24) -> 318.34253 | AC24: =SUM(P24:AA24) -> 571.69745 | AD24: =SUM(C24:AA24) -> 890.03998
A25: Anggaran marketing kas | B25: Rp | D25: =IF(D$5<=3,Asumsi!$D$84,IF(D$5<=12,Asumsi!$D$85,Asumsi!$D$86)) -> 5000000 | E25: =IF(E$5<=3,Asumsi!$D$84,IF(E$5<=12,Asumsi!$D$85,Asumsi!$D$86)) -> 5000000 | F25: =IF(F$5<=3,Asumsi!$D$84,IF(F$5<=12,Asumsi!$D$85,Asumsi!$D$86)) -> 5000000 | G25: =IF(G$5<=3,Asumsi!$D$84,IF(G$5<=12,Asumsi!$D$85,Asumsi!$D$86)) -> 25000000 | H25: =IF(H$5<=3,Asumsi!$D$84,IF(H$5<=12,Asumsi!$D$85,Asumsi!$D$86)) -> 25000000 | I25: =IF(I$5<=3,Asumsi!$D$84,IF(I$5<=12,Asumsi!$D$85,Asumsi!$D$86)) -> 25000000 | J25: =IF(J$5<=3,Asumsi!$D$84,IF(J$5<=12,Asumsi!$D$85,Asumsi!$D$86)) -> 25000000 | K25: =IF(K$5<=3,Asumsi!$D$84,IF(K$5<=12,Asumsi!$D$85,Asumsi!$D$86)) -> 25000000 | ... AA25: =IF(AA$5<=3,Asumsi!$D$84,IF(AA$5<=12,Asumsi!$D$85,Asumsi!$D$86)) -> 35000000 | AB25: =SUM(D25:O25) -> 240000000 | AC25: =SUM(P25:AA25) -> 420000000 | AD25: =SUM(C25:AA25) -> 660000000
A26: Pembeli baru — marketing (anggaran ÷ CAC) | B26: orang | D26: =IF(Asumsi!$D$87>0,D25/Asumsi!$D$87,0) -> 14.285714 | E26: =IF(Asumsi!$D$87>0,E25/Asumsi!$D$87,0) -> 14.285714 | F26: =IF(Asumsi!$D$87>0,F25/Asumsi!$D$87,0) -> 14.285714 | G26: =IF(Asumsi!$D$87>0,G25/Asumsi!$D$87,0) -> 71.428571 | H26: =IF(Asumsi!$D$87>0,H25/Asumsi!$D$87,0) -> 71.428571 | I26: =IF(Asumsi!$D$87>0,I25/Asumsi!$D$87,0) -> 71.428571 | J26: =IF(Asumsi!$D$87>0,J25/Asumsi!$D$87,0) -> 71.428571 | K26: =IF(Asumsi!$D$87>0,K25/Asumsi!$D$87,0) -> 71.428571 | ... AA26: =IF(Asumsi!$D$87>0,AA25/Asumsi!$D$87,0) -> 100 | AB26: =SUM(D26:O26) -> 685.71429 | AC26: =SUM(P26:AA26) -> 1200 | AD26: =SUM(C26:AA26) -> 1885.7143
A27: Basis pembeli retensi (awal bulan) | B27: orang | D27: =C36*(1-Asumsi!$D$88) -> 45 | E27: =D36*(1-Asumsi!$D$88) -> 58.247492 | F27: =E36*(1-Asumsi!$D$88) -> 75.114719 | G27: =F36*(1-Asumsi!$D$88) -> 94.866338 | H27: =G36*(1-Asumsi!$D$88) -> 120.2689 | I27: =H36*(1-Asumsi!$D$88) -> 147.9834 | J27: =I36*(1-Asumsi!$D$88) -> 177.57669 | K27: =J36*(1-Asumsi!$D$88) -> 208.68562 | ... AA27: =Z36*(1-Asumsi!$D$88) -> 826.41833
A28: Pembeli baru — referral (sebelum cap anggaran) | B28: orang | D28: =D27*Asumsi!$D$95 -> 0.675 | E28: =E27*Asumsi!$D$95 -> 0.87371239 | F28: =F27*Asumsi!$D$95 -> 1.1267208 | G28: =G27*Asumsi!$D$95 -> 1.4229951 | H28: =H27*Asumsi!$D$95 -> 1.8040335 | I28: =I27*Asumsi!$D$95 -> 2.2197511 | J28: =J27*Asumsi!$D$95 -> 2.6636503 | K28: =K27*Asumsi!$D$95 -> 3.1302843 | ... AA28: =AA27*Asumsi!$D$95 -> 12.396275 | AB28: =SUM(D28:O28) -> 31.419535 | AC28: =SUM(P28:AA28) -> 107.80941 | AD28: =SUM(C28:AA28) -> 139.22895
A29: Credit referral pembeli sebelum cap anggaran | B29: Rp | D29: =D28*Asumsi!$D$96*(MIN(Asumsi!$D$91,Asumsi!$D$94/Asumsi!$D$98)+Asumsi!$D$92)*Asumsi!$D$97 -> 15356.25 | E29: =E28*Asumsi!$D$96*(MIN(Asumsi!$D$91,Asumsi!$D$94/Asumsi!$D$98)+Asumsi!$D$92)*Asumsi!$D$97 -> 19876.957 | F29: =F28*Asumsi!$D$96*(MIN(Asumsi!$D$91,Asumsi!$D$94/Asumsi!$D$98)+Asumsi!$D$92)*Asumsi!$D$97 -> 25632.898 | G29: =G28*Asumsi!$D$96*(MIN(Asumsi!$D$91,Asumsi!$D$94/Asumsi!$D$98)+Asumsi!$D$92)*Asumsi!$D$97 -> 32373.138 | H29: =H28*Asumsi!$D$96*(MIN(Asumsi!$D$91,Asumsi!$D$94/Asumsi!$D$98)+Asumsi!$D$92)*Asumsi!$D$97 -> 41041.763 | I29: =I28*Asumsi!$D$96*(MIN(Asumsi!$D$91,Asumsi!$D$94/Asumsi!$D$98)+Asumsi!$D$92)*Asumsi!$D$97 -> 50499.337 | J29: =J28*Asumsi!$D$96*(MIN(Asumsi!$D$91,Asumsi!$D$94/Asumsi!$D$98)+Asumsi!$D$92)*Asumsi!$D$97 -> 60598.044 | K29: =K28*Asumsi!$D$96*(MIN(Asumsi!$D$91,Asumsi!$D$94/Asumsi!$D$98)+Asumsi!$D$92)*Asumsi!$D$97 -> 71213.969 | ... AA29: =AA28*Asumsi!$D$96*(MIN(Asumsi!$D$91,Asumsi!$D$94/Asumsi!$D$98)+Asumsi!$D$92)*Asumsi!$D$97 -> 282015.26 | AB29: =SUM(D29:O29) -> 714794.43 | AC29: =SUM(P29:AA29) -> 2452664.1 | AD29: =SUM(C29:AA29) -> 3167458.5
A30: Faktor cap anggaran referral global | B30: faktor | D30: =IF(AND(Asumsi!$D$103=1,D29>0),MIN(1,Asumsi!$D$104/D29),1) -> 1 | E30: =IF(AND(Asumsi!$D$103=1,E29>0),MIN(1,Asumsi!$D$104/E29),1) -> 1 | F30: =IF(AND(Asumsi!$D$103=1,F29>0),MIN(1,Asumsi!$D$104/F29),1) -> 1 | G30: =IF(AND(Asumsi!$D$103=1,G29>0),MIN(1,Asumsi!$D$104/G29),1) -> 1 | H30: =IF(AND(Asumsi!$D$103=1,H29>0),MIN(1,Asumsi!$D$104/H29),1) -> 1 | I30: =IF(AND(Asumsi!$D$103=1,I29>0),MIN(1,Asumsi!$D$104/I29),1) -> 1 | J30: =IF(AND(Asumsi!$D$103=1,J29>0),MIN(1,Asumsi!$D$104/J29),1) -> 1 | K30: =IF(AND(Asumsi!$D$103=1,K29>0),MIN(1,Asumsi!$D$104/K29),1) -> 1 | ... AA30: =IF(AND(Asumsi!$D$103=1,AA29>0),MIN(1,Asumsi!$D$104/AA29),1) -> 1
A31: Pembeli baru — referral (efektif) | B31: orang | D31: =D28*D30 -> 0.675 | E31: =E28*E30 -> 0.87371239 | F31: =F28*F30 -> 1.1267208 | G31: =G28*G30 -> 1.4229951 | H31: =H28*H30 -> 1.8040335 | I31: =I28*I30 -> 2.2197511 | J31: =J28*J30 -> 2.6636503 | K31: =K28*K30 -> 3.1302843 | ... AA31: =AA28*AA30 -> 12.396275 | AB31: =SUM(D31:O31) -> 31.419535 | AC31: =SUM(P31:AA31) -> 107.80941 | AD31: =SUM(C31:AA31) -> 139.22895
A32: Total pembeli baru (permintaan) | B32: orang | D32: =D24+D26+D31 -> 34.960714 | E32: =E24+E26+E31 -> 36.159427 | F32: =F24+F26+F31 -> 37.462435 | G32: =G24+G26+G31 -> 96.004066 | H32: =H24+H26+H31 -> 97.54273 | I32: =I24+I26+I31 -> 99.173954 | J32: =J24+J26+J31 -> 100.89413 | K32: =K24+K26+K31 -> 102.70086 | ... AA32: =AA24+AA26+AA31 -> 173.82675 | AB32: =SUM(D32:O32) -> 1035.4764 | AC32: =SUM(P32:AA32) -> 1879.5069 | AD32: =SUM(C32:AA32) -> 2914.9832
A33: Permintaan transaksi | B33: transaksi | D33: =D32+D27*Asumsi!$D$89 -> 38.560714 | E33: =E32+E27*Asumsi!$D$89 -> 40.819226 | F33: =F32+F27*Asumsi!$D$89 -> 43.471613 | G33: =G32+G27*Asumsi!$D$89 -> 103.59337 | H33: =H32+H27*Asumsi!$D$89 -> 107.16424 | I33: =I32+I27*Asumsi!$D$89 -> 111.01263 | J33: =J32+J27*Asumsi!$D$89 -> 115.10027 | K33: =K32+K27*Asumsi!$D$89 -> 119.39571 | ... AA33: =AA32+AA27*Asumsi!$D$89 -> 239.94022 | AB33: =SUM(D33:O33) -> 1203.0472 | AC33: =SUM(P33:AA33) -> 2454.4904 | AD33: =SUM(C33:AA33) -> 3657.5376
A34: Transaksi dibayar = MIN(permintaan, kapasitas) | B34: transaksi | D34: =MIN(D33,D22) -> 21.75 | E34: =MIN(E33,E22) -> 28.4625 | F34: =MIN(F33,F22) -> 35.151375 | G34: =MIN(G33,G22) -> 41.830286 | H34: =MIN(H33,H22) -> 48.512711 | I34: =MIN(I33,I22) -> 55.211972 | J34: =MIN(J33,J22) -> 61.941266 | K34: =MIN(K33,K22) -> 68.713691 | ... AA34: =MIN(AA33,AA22) -> 193.6561 | AB34: =SUM(D34:O34) -> 705.47065 | AC34: =SUM(P34:AA34) -> 1762.4541 | AD34: =SUM(C34:AA34) -> 2467.9248
A35: Fill rate (likuiditas) | B35: % | D35: =IF(D33>0,D34/D33,0) -> 0.56404557 | E35: =IF(E33>0,E34/E33,0) -> 0.69728172 | F35: =IF(F33>0,F34/F33,0) -> 0.80860527 | G35: =IF(G33>0,G34/G33,0) -> 0.40379307 | H35: =IF(H33>0,H34/H33,0) -> 0.45269495 | I35: =IF(I33>0,I34/I33,0) -> 0.49734858 | J35: =IF(J33>0,J34/J33,0) -> 0.53815049 | K35: =IF(K33>0,K34/K33,0) -> 0.57551221 | ... AD35: =IF(AD33>0,AD34/AD33,0) -> 0.67475035
A36: Basis pembeli (akhir bulan) | B36: orang | C36: =Asumsi!$D$81 -> 50 | D36: =D27+D32*D35 -> 64.719436 | E36: =E27+E32*E35 -> 83.460799 | F36: =F27+F32*F35 -> 105.40704 | G36: =G27+G32*G35 -> 133.63211 | H36: =H27+H32*H35 -> 164.426 | I36: =I27+I32*I35 -> 197.30743 | J36: =J27+J32*J35 -> 231.87291 | K36: =K27+K32*K35 -> 267.79122 | ... AA36: =AA27+AA32*AA35 -> 966.71415 | AB36: =O36 -> 420.4844 | AC36: =AA36 -> 966.71415 | AD36: =AA36 -> 966.71415
A37: Transaksi batal setelah bayar | B37: transaksi | D37: =D34*Asumsi!$D$65 -> 1.74 | E37: =E34*Asumsi!$D$65 -> 2.277 | F37: =F34*Asumsi!$D$65 -> 2.81211 | G37: =G34*Asumsi!$D$65 -> 3.3464229 | H37: =H34*Asumsi!$D$65 -> 3.8810169 | I37: =I34*Asumsi!$D$65 -> 4.4169578 | J37: =J34*Asumsi!$D$65 -> 4.9553013 | K37: =K34*Asumsi!$D$65 -> 5.4970953 | ... AA37: =AA34*Asumsi!$D$65 -> 15.492488 | AB37: =SUM(D37:O37) -> 56.437652 | AC37: =SUM(P37:AA37) -> 140.99633 | AD37: =SUM(C37:AA37) -> 197.43398
A38: Transaksi selesai (COMPLETED) | B38: transaksi | D38: =D34-D37 -> 20.01 | E38: =E34-E37 -> 26.1855 | F38: =F34-F37 -> 32.339265 | G38: =G34-G37 -> 38.483863 | H38: =H34-H37 -> 44.631694 | I38: =I34-I37 -> 50.795015 | J38: =J34-J37 -> 56.985965 | K38: =K34-K37 -> 63.216596 | ... AA38: =AA34-AA37 -> 178.16361 | AB38: =SUM(D38:O38) -> 649.033 | AC38: =SUM(P38:AA38) -> 1621.4578 | AD38: =SUM(C38:AA38) -> 2270.4908
A39: Sisi pembatas | B39: teks | D39: =IF(D33>D22,"Pasokan","Permintaan") -> Pasokan | E39: =IF(E33>E22,"Pasokan","Permintaan") -> Pasokan | F39: =IF(F33>F22,"Pasokan","Permintaan") -> Pasokan | G39: =IF(G33>G22,"Pasokan","Permintaan") -> Pasokan | H39: =IF(H33>H22,"Pasokan","Permintaan") -> Pasokan | I39: =IF(I33>I22,"Pasokan","Permintaan") -> Pasokan | J39: =IF(J33>J22,"Pasokan","Permintaan") -> Pasokan | K39: =IF(K33>K22,"Pasokan","Permintaan") -> Pasokan | ... AA39: =IF(AA33>AA22,"Pasokan","Permintaan") -> Pasokan
A40: Nilai & pendapatan
A41: GMV bruto (Σ TOTAL transaksi selesai) | B41: Rp | D41: =D38*'Unit Economics'!$C$18 -> 43788237 | E41: =E38*'Unit Economics'!$C$18 -> 57302193 | F41: =F38*'Unit Economics'!$C$18 -> 70768585 | G41: =G38*'Unit Economics'!$C$18 -> 84214919 | H41: =H38*'Unit Economics'!$C$18 -> 97668326 | I41: =I38*'Unit Economics'!$C$18 -> 1.1115563e+08 | J41: =J38*'Unit Economics'!$C$18 -> 1.2470339e+08 | K41: =K38*'Unit Economics'!$C$18 -> 1.3833799e+08 | ... AA41: =AA38*'Unit Economics'!$C$18 -> 3.8987858e+08 | AB41: =SUM(D41:O41) -> 1.4202904e+09 | AC41: =SUM(P41:AA41) -> 3.5482647e+09 | AD41: =SUM(C41:AA41) -> 4.9685551e+09
A42: Nilai barang (pass-through) | B42: Rp | D42: =D38*'Unit Economics'!$C$8 -> 30015000 | E42: =E38*'Unit Economics'!$C$8 -> 39278250 | F42: =F38*'Unit Economics'!$C$8 -> 48508898 | G42: =G38*'Unit Economics'!$C$8 -> 57725795 | H42: =H38*'Unit Economics'!$C$8 -> 66947541 | I42: =I38*'Unit Economics'!$C$8 -> 76192522 | J42: =J38*'Unit Economics'!$C$8 -> 85478948 | K42: =K38*'Unit Economics'!$C$8 -> 94824894 | ... AA42: =AA38*'Unit Economics'!$C$8 -> 2.6724541e+08 | AB42: =SUM(D42:O42) -> 9.735495e+08 | AC42: =SUM(P42:AA42) -> 2.4321867e+09 | AD42: =SUM(C42:AA42) -> 3.4057362e+09
A43: Pendapatan bruto platform (platform + protection fee) | B43: Rp | D43: =D38*'Unit Economics'!$C$47 -> 1950975 | E43: =E38*'Unit Economics'!$C$47 -> 2553086.2 | F43: =F38*'Unit Economics'!$C$47 -> 3153078.3 | G43: =G38*'Unit Economics'!$C$47 -> 3752176.7 | H43: =H38*'Unit Economics'!$C$47 -> 4351590.2 | I43: =I38*'Unit Economics'!$C$47 -> 4952513.9 | J43: =J38*'Unit Economics'!$C$47 -> 5556131.6 | K43: =K38*'Unit Economics'!$C$47 -> 6163618.1 | ... AA43: =AA38*'Unit Economics'!$C$47 -> 17370952 | AB43: =SUM(D43:O43) -> 63280718 | AC43: =SUM(P43:AA43) -> 1.5809213e+08 | AD43: =SUM(C43:AA43) -> 2.2137285e+08
...

Sheet Sensitivitas
A1: Analisis Sensitivitas — skenario aktif
A2: ="Semua tabel memakai skenario aktif: "&Asumsi!$D$4&" (ubah di Asumsi!D4). Sel biru = sumbu yang boleh diubah." -> Semua tabel memakai skenario aktif: Dasar (ubah di Asumsi!D4). Sel biru = sumbu yang boleh diubah.
A4: Basis dari skenario aktif
B5: GMV per transaksi (TOTAL) | C5: =INDEX('Unit Economics'!$C$18:$E$18,Asumsi!$D$5) -> 2920133.6
B6: Nilai barang per transaksi | C6: =INDEX('Unit Economics'!$C$8:$E$8,Asumsi!$D$5) -> 2000000
B7: Biaya variabel per transaksi (subsidi bayar, payout, klaim, CS, chargeback, batal) | C7: =INDEX('Unit Economics'!$C$58:$E$58,Asumsi!$D$5) -> 45640.3
B8: Biaya tetap + marketing per bulan (rata-rata Th2, tanpa biaya sekali) | C8: =CHOOSE(Asumsi!$D$5,('Proyeksi 24 Bulan'!$AC$71-'Proyeksi 24 Bulan'!$AC$69)/12,('Proyeksi 24 Bulan'!$AC$134-'Proyeksi 24 Bulan'!$AC$132)/12,('Proyeksi 24 Bulan'!$AC$197-'Proyeksi 24 Bulan'!$AC$195)/12) -> 1.6388908e+08
B9: Take rate bersih saat ini (pendapatan bersih ÷ GMV) | C9: =INDEX('Unit Economics'!$C$62:$E$62,Asumsi!$D$5) -> 0.042086535
B10: Pendapatan bersih per transaksi saat ini | C10: =INDEX('Unit Economics'!$C$50:$E$50,Asumsi!$D$5) -> 122898.31
B11: Margin kontribusi per transaksi saat ini | C11: =INDEX('Unit Economics'!$C$57:$E$57,Asumsi!$D$5) -> 77258.008
B12: BEP transaksi/bulan saat ini | C12: =IF(C11>0,ROUNDUP(C8/C11,0),"CM ≤ 0") -> 2122
A14: 1. EBITDA bulanan (Rp juta) = transaksi × (take rate bersih × GMV/trx − biaya variabel/trx) − biaya tetap & marketing
B15: Take rate bersih ↓ · transaksi selesai/bulan → | C15: 250 | D15: 500 | E15: 1000 | F15: 1500 | G15: 2000 | H15: 3000 | I15: 5000 | J15: 7500 | K15: 10000 | L15: Setara % nilai barang
B16: 0.03 | C16: =(C$15*($B16*$C$5-$C$7)-$C$8)/1000000 -> -153.39815 | D16: =(D$15*($B16*$C$5-$C$7)-$C$8)/1000000 -> -142.90722 | E16: =(E$15*($B16*$C$5-$C$7)-$C$8)/1000000 -> -121.92537 | F16: =(F$15*($B16*$C$5-$C$7)-$C$8)/1000000 -> -100.94351 | G16: =(G$15*($B16*$C$5-$C$7)-$C$8)/1000000 -> -79.961657 | H16: =(H$15*($B16*$C$5-$C$7)-$C$8)/1000000 -> -37.997948 | I16: =(I$15*($B16*$C$5-$C$7)-$C$8)/1000000 -> 45.929471 | J16: =(J$15*($B16*$C$5-$C$7)-$C$8)/1000000 -> 150.83874 | K16: =(K$15*($B16*$C$5-$C$7)-$C$8)/1000000 -> 255.74802 | L16: =IF($C$6>0,$B16*$C$5/$C$6,0) -> 0.043802005
B17: 0.035 | C17: =(C$15*($B17*$C$5-$C$7)-$C$8)/1000000 -> -149.74798 | D17: =(D$15*($B17*$C$5-$C$7)-$C$8)/1000000 -> -135.60689 | E17: =(E$15*($B17*$C$5-$C$7)-$C$8)/1000000 -> -107.3247 | F17: =(F$15*($B17*$C$5-$C$7)-$C$8)/1000000 -> -79.04251 | G17: =(G$15*($B17*$C$5-$C$7)-$C$8)/1000000 -> -50.760321 | H17: =(H$15*($B17*$C$5-$C$7)-$C$8)/1000000 -> 5.804057 | I17: =(I$15*($B17*$C$5-$C$7)-$C$8)/1000000 -> 118.93281 | J17: =(J$15*($B17*$C$5-$C$7)-$C$8)/1000000 -> 260.34376 | K17: =(K$15*($B17*$C$5-$C$7)-$C$8)/1000000 -> 401.7547 | L17: =IF($C$6>0,$B17*$C$5/$C$6,0) -> 0.051102339
B18: 0.04 | C18: =(C$15*($B18*$C$5-$C$7)-$C$8)/1000000 -> -146.09781 | D18: =(D$15*($B18*$C$5-$C$7)-$C$8)/1000000 -> -128.30655 | E18: =(E$15*($B18*$C$5-$C$7)-$C$8)/1000000 -> -92.72403 | F18: =(F$15*($B18*$C$5-$C$7)-$C$8)/1000000 -> -57.141507 | G18: =(G$15*($B18*$C$5-$C$7)-$C$8)/1000000 -> -21.558984 | H18: =(H$15*($B18*$C$5-$C$7)-$C$8)/1000000 -> 49.606062 | I18: =(I$15*($B18*$C$5-$C$7)-$C$8)/1000000 -> 191.93615 | J18: =(J$15*($B18*$C$5-$C$7)-$C$8)/1000000 -> 369.84877 | K18: =(K$15*($B18*$C$5-$C$7)-$C$8)/1000000 -> 547.76138 | L18: =IF($C$6>0,$B18*$C$5/$C$6,0) -> 0.058402673
B19: 0.045 | C19: =(C$15*($B19*$C$5-$C$7)-$C$8)/1000000 -> -142.44765 | D19: =(D$15*($B19*$C$5-$C$7)-$C$8)/1000000 -> -121.00622 | E19: =(E$15*($B19*$C$5-$C$7)-$C$8)/1000000 -> -78.123362 | F19: =(F$15*($B19*$C$5-$C$7)-$C$8)/1000000 -> -35.240505 | G19: =(G$15*($B19*$C$5-$C$7)-$C$8)/1000000 -> 7.6423522 | H19: =(H$15*($B19*$C$5-$C$7)-$C$8)/1000000 -> 93.408067 | I19: =(I$15*($B19*$C$5-$C$7)-$C$8)/1000000 -> 264.9395 | J19: =(J$15*($B19*$C$5-$C$7)-$C$8)/1000000 -> 479.35378 | K19: =(K$15*($B19*$C$5-$C$7)-$C$8)/1000000 -> 693.76807 | L19: =IF($C$6>0,$B19*$C$5/$C$6,0) -> 0.065703007
B20: 0.05 | C20: =(C$15*($B20*$C$5-$C$7)-$C$8)/1000000 -> -138.79748 | D20: =(D$15*($B20*$C$5-$C$7)-$C$8)/1000000 -> -113.70588 | E20: =(E$15*($B20*$C$5-$C$7)-$C$8)/1000000 -> -63.522694 | F20: =(F$15*($B20*$C$5-$C$7)-$C$8)/1000000 -> -13.339503 | G20: =(G$15*($B20*$C$5-$C$7)-$C$8)/1000000 -> 36.843689 | H20: =(H$15*($B20*$C$5-$C$7)-$C$8)/1000000 -> 137.21007 | I20: =(I$15*($B20*$C$5-$C$7)-$C$8)/1000000 -> 337.94284 | J20: =(J$15*($B20*$C$5-$C$7)-$C$8)/1000000 -> 588.85879 | K20: =(K$15*($B20*$C$5-$C$7)-$C$8)/1000000 -> 839.77475 | L20: =IF($C$6>0,$B20*$C$5/$C$6,0) -> 0.073003341
B21: 0.055 | C21: =(C$15*($B21*$C$5-$C$7)-$C$8)/1000000 -> -135.14731 | D21: =(D$15*($B21*$C$5-$C$7)-$C$8)/1000000 -> -106.40555 | E21: =(E$15*($B21*$C$5-$C$7)-$C$8)/1000000 -> -48.922025 | F21: =(F$15*($B21*$C$5-$C$7)-$C$8)/1000000 -> 8.5614999 | G21: =(G$15*($B21*$C$5-$C$7)-$C$8)/1000000 -> 66.045025 | H21: =(H$15*($B21*$C$5-$C$7)-$C$8)/1000000 -> 181.01208 | I21: =(I$15*($B21*$C$5-$C$7)-$C$8)/1000000 -> 410.94618 | J21: =(J$15*($B21*$C$5-$C$7)-$C$8)/1000000 -> 698.3638 | K21: =(K$15*($B21*$C$5-$C$7)-$C$8)/1000000 -> 985.78143 | L21: =IF($C$6>0,$B21*$C$5/$C$6,0) -> 0.080303675
B22: 0.06 | C22: =(C$15*($B22*$C$5-$C$7)-$C$8)/1000000 -> -131.49715 | D22: =(D$15*($B22*$C$5-$C$7)-$C$8)/1000000 -> -99.105217 | E22: =(E$15*($B22*$C$5-$C$7)-$C$8)/1000000 -> -34.321357 | F22: =(F$15*($B22*$C$5-$C$7)-$C$8)/1000000 -> 30.462502 | G22: =(G$15*($B22*$C$5-$C$7)-$C$8)/1000000 -> 95.246362 | H22: =(H$15*($B22*$C$5-$C$7)-$C$8)/1000000 -> 224.81408 | I22: =(I$15*($B22*$C$5-$C$7)-$C$8)/1000000 -> 483.94952 | J22: =(J$15*($B22*$C$5-$C$7)-$C$8)/1000000 -> 807.86882 | K22: =(K$15*($B22*$C$5-$C$7)-$C$8)/1000000 -> 1131.7881 | L22: =IF($C$6>0,$B22*$C$5/$C$6,0) -> 0.087604009
B23: 0.07 | C23: =(C$15*($B23*$C$5-$C$7)-$C$8)/1000000 -> -124.19681 | D23: =(D$15*($B23*$C$5-$C$7)-$C$8)/1000000 -> -84.504548 | E23: =(E$15*($B23*$C$5-$C$7)-$C$8)/1000000 -> -5.1200207 | F23: =(F$15*($B23*$C$5-$C$7)-$C$8)/1000000 -> 74.264507 | G23: =(G$15*($B23*$C$5-$C$7)-$C$8)/1000000 -> 153.64903 | H23: =(H$15*($B23*$C$5-$C$7)-$C$8)/1000000 -> 312.41809 | I23: =(I$15*($B23*$C$5-$C$7)-$C$8)/1000000 -> 629.9562 | J23: =(J$15*($B23*$C$5-$C$7)-$C$8)/1000000 -> 1026.8788 | K23: =(K$15*($B23*$C$5-$C$7)-$C$8)/1000000 -> 1423.8015 | L23: =IF($C$6>0,$B23*$C$5/$C$6,0) -> 0.10220468
B24: Penyederhanaan: biaya variabel per transaksi dianggap tetap terhadap take rate (klaim proteksi sebenarnya ikut protection fee).
A26: 2. Subsidi kanal pembayaran: biaya VA yang dibebankan ke pembeli × porsi VA (skenario aktif)
B27: Biaya Xendit per transaksi VA | C27: =INDEX('Unit Economics'!$C$22:$E$22,Asumsi!$D$5) -> 14430
B28: VA dibebankan saat ini (config) | C28: =INDEX('Unit Economics'!$C$21:$E$21,Asumsi!$D$5) -> 4500
B29: Porsi VA saat ini | C29: =INDEX('Unit Economics'!$C$114:$E$114,Asumsi!$D$5) -> 0.5
B30: Subsidi rata-rata saat ini (bauran) | C30: =INDEX('Unit Economics'!$C$35:$E$35,Asumsi!$D$5) -> 16233.3
B31: Biaya bayar rata-rata yang dibebankan ke pembeli (bauran) | C31: =INDEX('Unit Economics'!$C$33:$E$33,Asumsi!$D$5) -> 22833.65
B32: TOTAL dibayar pembeli saat ini | C32: =INDEX('Unit Economics'!$C$18:$E$18,Asumsi!$D$5) -> 2920133.6
B33: Subsidi rata-rata per transaksi non-VA | C33: =IF(1-C29>0,(C30-C29*(C27-C28))/(1-C29),0) -> 22536.6
B35: Tabel 2a — Margin kontribusi per transaksi (Rp)
B36: VA dibebankan (Rp) ↓ · porsi VA → | C36: 0.3 | D36: 0.4 | E36: 0.5 | F36: 0.6 | G36: 0.7
B37: 0 | C37: =$C$11+$C$30-(C$36*($C$27-$B37)+(1-C$36)*$C$33) -> 73386.688 | D37: =$C$11+$C$30-(D$36*($C$27-$B37)+(1-D$36)*$C$33) -> 74197.348 | E37: =$C$11+$C$30-(E$36*($C$27-$B37)+(1-E$36)*$C$33) -> 75008.008 | F37: =$C$11+$C$30-(F$36*($C$27-$B37)+(1-F$36)*$C$33) -> 75818.668 | G37: =$C$11+$C$30-(G$36*($C$27-$B37)+(1-G$36)*$C$33) -> 76629.328
B38: 4500 | C38: =$C$11+$C$30-(C$36*($C$27-$B38)+(1-C$36)*$C$33) -> 74736.688 | D38: =$C$11+$C$30-(D$36*($C$27-$B38)+(1-D$36)*$C$33) -> 75997.348 | E38: =$C$11+$C$30-(E$36*($C$27-$B38)+(1-E$36)*$C$33) -> 77258.008 | F38: =$C$11+$C$30-(F$36*($C$27-$B38)+(1-F$36)*$C$33) -> 78518.668 | G38: =$C$11+$C$30-(G$36*($C$27-$B38)+(1-G$36)*$C$33) -> 79779.328
B39: 7500 | C39: =$C$11+$C$30-(C$36*($C$27-$B39)+(1-C$36)*$C$33) -> 75636.688 | D39: =$C$11+$C$30-(D$36*($C$27-$B39)+(1-D$36)*$C$33) -> 77197.348 | E39: =$C$11+$C$30-(E$36*($C$27-$B39)+(1-E$36)*$C$33) -> 78758.008 | F39: =$C$11+$C$30-(F$36*($C$27-$B39)+(1-F$36)*$C$33) -> 80318.668 | G39: =$C$11+$C$30-(G$36*($C$27-$B39)+(1-G$36)*$C$33) -> 81879.328
B40: 10000 | C40: =$C$11+$C$30-(C$36*($C$27-$B40)+(1-C$36)*$C$33) -> 76386.688 | D40: =$C$11+$C$30-(D$36*($C$27-$B40)+(1-D$36)*$C$33) -> 78197.348 | E40: =$C$11+$C$30-(E$36*($C$27-$B40)+(1-E$36)*$C$33) -> 80008.008 | F40: =$C$11+$C$30-(F$36*($C$27-$B40)+(1-F$36)*$C$33) -> 81818.668 | G40: =$C$11+$C$30-(G$36*($C$27-$B40)+(1-G$36)*$C$33) -> 83629.328
B41: 14430 | C41: =$C$11+$C$30-(C$36*($C$27-$B41)+(1-C$36)*$C$33) -> 77715.688 | D41: =$C$11+$C$30-(D$36*($C$27-$B41)+(1-D$36)*$C$33) -> 79969.348 | E41: =$C$11+$C$30-(E$36*($C$27-$B41)+(1-E$36)*$C$33) -> 82223.008 | F41: =$C$11+$C$30-(F$36*($C$27-$B41)+(1-F$36)*$C$33) -> 84476.668 | G41: =$C$11+$C$30-(G$36*($C$27-$B41)+(1-G$36)*$C$33) -> 86730.328
B43: Tabel 2b — BEP transaksi selesai per bulan (biaya tetap + marketing Th2 ÷ CM)
B44: VA dibebankan (Rp) ↓ · porsi VA → | C44: =C36 -> 0.3 | D44: =D36 -> 0.4 | E44: =E36 -> 0.5 | F44: =F36 -> 0.6 | G44: =G36 -> 0.7
B45: =B37 -> 0 | C45: =IF(C37>0,ROUNDUP($C$8/C37,0),"CM ≤ 0") -> 2234 | D45: =IF(D37>0,ROUNDUP($C$8/D37,0),"CM ≤ 0") -> 2209 | E45: =IF(E37>0,ROUNDUP($C$8/E37,0),"CM ≤ 0") -> 2185 | F45: =IF(F37>0,ROUNDUP($C$8/F37,0),"CM ≤ 0") -> 2162 | G45: =IF(G37>0,ROUNDUP($C$8/G37,0),"CM ≤ 0") -> 2139
...

Sheet Sumber
A1: Sumber & Catatan Keterbatasan Data
A2: Repo: /home/claude/jastipkita (dibaca 2026-10-04). URL publik diakses 2026-10-04 kecuali disebut lain.
A4: No | B4: Sumber | C4: Lokasi (path repo / URL) | D4: Dipakai untuk | E4: Tanggal akses / verifikasi | F4: Status
A5: 1 | B5: Business config default v1 | C5: packages/core/src/config/business-config.defaults.json | D5: Platform fee 5% (Rp10 rb–750 rb), protection 1,5% (Rp5 rb–300 rb), PPN layanan 12% × 0,916667, traveler fee min Rp25 rb & maks 30%, biaya kanal dibebankan (VA Rp4.500, QRIS 0,7%, e-wallet 1,5%, kartu Rp2.000 + 2,9%), referral (Rp25 rb/25 rb, min Rp500 rb, cap Rp250 rb/bln, traveler Rp50 rb), limit transaksi, payoutFeeIdr 0, markup FX | E5: 2026-10-04 | F5: Repo (config bertanda asumsi untuk payment_fees, service_tax, limits)
A6: 2 | B6: Pricing engine | C6: packages/core/src/pricing/index.ts | D6: Urutan hitung 11 baris, clamp fee, batas traveler fee (cap lalu min), gross-up biaya bayar T = ceil((P + fixed)/(1 − r)), PPN atas platform + protection, alokasi bucket | E6: 2026-10-04 | F6: Repo
A7: 3 | B7: Domain model | C7: docs/00-domain-model.md §9–§10 | D7: Daftar & urutan 11 baris harga; bucket ledger | E7: 2026-10-04 | F7: Repo
A8: 4 | B8: Payments & ledger | C8: docs/04-payments-ledger.md | D8: COMPLETION_RELEASE: traveler menerima harga aktual + bea dibayar + traveler fee; sisa dana barang/bea dikembalikan ke pembeli (markup FX bukan pendapatan); refund VA via payout | E8: 2026-10-04 | F8: Repo
A9: 5 | B9: Seed aturan bea | C9: db/seeds/0100_customs_rules.sql (ID_PAX_NON_PERSONAL v1) | D9: BM 10%, PPN 12% × 0,916667, PPh 5%, pembulatan CEIL_1000 semua komponen | E9: 2026-10-04 | F9: Repo — status DRAFT sampai verifikasi konsultan (L7)
